from utils.error import CustomException


class EthdoError(CustomException):
    """Exception raised for errors in the ethdo call functions."""

    pass
